<?xml version="1.0"?>
<!--
  Gazebo ROS ackermann drive plugin demo

  Try sending commands:

    ros2 topic pub /demo/cmd_demo geometry_msgs/msg/Twist '{linear: {x: 1.0}, angular: {z: 0.1}}' -1

  Try listening to odometry:

    ros2 topic echo /demo/odom_demo

  Try listening to odometer reading(linear distance convered):

    ros2 topic echo /demo/distance_demo

  Try listening to TF:

    ros2 run tf2_ros tf2_echo odom_demo chassis

    and other links
-->
<sdf version="1.6">
  <world name="default">
    <light name='sun' type='directional'>
      <cast_shadows>1</cast_shadows>
      <pose>0 0 10 0 -0 0</pose>
      <diffuse>0.8 0.8 0.8 1</diffuse>
      <specular>0.2 0.2 0.2 1</specular>
      <attenuation>
        <range>1000</range>
        <constant>0.9</constant>
        <linear>0.01</linear>
        <quadratic>0.001</quadratic>
      </attenuation>
      <direction>-0.5 0.1 -0.9</direction>
      <spot>
        <inner_angle>0</inner_angle>
        <outer_angle>0</outer_angle>
        <falloff>0</falloff>
      </spot>
    </light>
    <model name='ground_plane'>
      <static>1</static>
      <link name='link'>
        <collision name='collision'>
          <geometry>
            <plane>
              <normal>0 0 1</normal>
              <size>100 100</size>
            </plane>
          </geometry>
          <surface>
            <contact>
              <collide_bitmask>65535</collide_bitmask>
              <ode/>
            </contact>
            <friction>
              <ode>
                <mu>100</mu>
                <mu2>50</mu2>
              </ode>
              <torsional>
                <ode/>
              </torsional>
            </friction>
            <bounce/>
          </surface>
          <max_contacts>10</max_contacts>
        </collision>
        <visual name='visual'>
          <cast_shadows>0</cast_shadows>
          <geometry>
            <plane>
              <normal>0 0 1</normal>
              <size>100 100</size>
            </plane>
          </geometry>
          <material>
            <script>
              <uri>file://media/materials/scripts/gazebo.material</uri>
              <name>Gazebo/Grey</name>
            </script>
          </material>
        </visual>
        <self_collide>0</self_collide>
        <enable_wind>0</enable_wind>
        <kinematic>0</kinematic>
      </link>
    </model>
    <gravity>0 0 -9.8</gravity>
    <magnetic_field>6e-06 2.3e-05 -4.2e-05</magnetic_field>
    <atmosphere type='adiabatic'/>
    <physics type='ode'>
      <max_step_size>0.001</max_step_size>
      <real_time_factor>1</real_time_factor>
      <real_time_update_rate>1000</real_time_update_rate>
    </physics>
    <scene>
      <ambient>0.4 0.4 0.4 1</ambient>
      <background>0.7 0.7 0.7 1</background>
      <shadows>1</shadows>
    </scene>
    <wind/>
    <spherical_coordinates>
      <surface_model>EARTH_WGS84</surface_model>
      <latitude_deg>0</latitude_deg>
      <longitude_deg>0</longitude_deg>
      <elevation>0</elevation>
      <heading_deg>0</heading_deg>
    </spherical_coordinates>
    <model name='Construction Cone'>
      <link name='link'>
        <collision name='collision'>
          <geometry>
            <mesh>
              <scale>100 100 100</scale>
              <uri>model://construction_cone/meshes/construction_cone.dae</uri>
            </mesh>
          </geometry>
          <max_contacts>10</max_contacts>
          <surface>
            <contact>
              <ode/>
            </contact>
            <bounce/>
            <friction>
              <torsional>
                <ode/>
              </torsional>
              <ode/>
            </friction>
          </surface>
        </collision>
        <visual name='visual'>
          <geometry>
            <mesh>
              <scale>100 100 100</scale>
              <uri>model://construction_cone/meshes/construction_cone.dae</uri>
            </mesh>
          </geometry>
        </visual>
        <self_collide>0</self_collide>
        <inertial>
          <pose>0 0 0 0 -0 0</pose>
          <inertia>
            <ixx>1</ixx>
            <ixy>0</ixy>
            <ixz>0</ixz>
            <iyy>1</iyy>
            <iyz>0</iyz>
            <izz>1</izz>
          </inertia>
          <mass>1</mass>
        </inertial>
        <enable_wind>0</enable_wind>
        <kinematic>0</kinematic>
      </link>
      <pose>-4.31803 -1.21562 0 0 -0 0</pose>
    </model>
    <model name='Construction Cone_clone'>
      <link name='link'>
        <collision name='collision'>
          <geometry>
            <mesh>
              <scale>100 100 100</scale>
              <uri>model://construction_cone/meshes/construction_cone.dae</uri>
            </mesh>
          </geometry>
          <max_contacts>10</max_contacts>
          <surface>
            <contact>
              <ode/>
            </contact>
            <bounce/>
            <friction>
              <torsional>
                <ode/>
              </torsional>
              <ode/>
            </friction>
          </surface>
        </collision>
        <visual name='visual'>
          <geometry>
            <mesh>
              <scale>100 100 100</scale>
              <uri>model://construction_cone/meshes/construction_cone.dae</uri>
            </mesh>
          </geometry>
        </visual>
        <self_collide>0</self_collide>
        <inertial>
          <pose>0 0 0 0 -0 0</pose>
          <inertia>
            <ixx>1</ixx>
            <ixy>0</ixy>
            <ixz>0</ixz>
            <iyy>1</iyy>
            <iyz>0</iyz>
            <izz>1</izz>
          </inertia>
          <mass>1</mass>
        </inertial>
        <enable_wind>0</enable_wind>
        <kinematic>0</kinematic>
      </link>
      <pose>-3 1 -0 0 -1e-06 0</pose>
    </model>
    <model name='Construction Cone_clone_0'>
      <link name='link'>
        <collision name='collision'>
          <geometry>
            <mesh>
              <scale>100 100 100</scale>
              <uri>model://construction_cone/meshes/construction_cone.dae</uri>
            </mesh>
          </geometry>
          <max_contacts>10</max_contacts>
          <surface>
            <contact>
              <ode/>
            </contact>
            <bounce/>
            <friction>
              <torsional>
                <ode/>
              </torsional>
              <ode/>
            </friction>
          </surface>
        </collision>
        <visual name='visual'>
          <geometry>
            <mesh>
              <scale>100 100 100</scale>
              <uri>model://construction_cone/meshes/construction_cone.dae</uri>
            </mesh>
          </geometry>
        </visual>
        <self_collide>0</self_collide>
        <inertial>
          <pose>0 0 0 0 -0 0</pose>
          <inertia>
            <ixx>1</ixx>
            <ixy>0</ixy>
            <ixz>0</ixz>
            <iyy>1</iyy>
            <iyz>0</iyz>
            <izz>1</izz>
          </inertia>
          <mass>1</mass>
        </inertial>
        <enable_wind>0</enable_wind>
        <kinematic>0</kinematic>
      </link>
      <pose>-1.12259 2.67344 -0 0 -1e-06 0</pose>
    </model>
    <model name='Construction Cone_clone_1'>
      <link name='link'>
        <collision name='collision'>
          <geometry>
            <mesh>
              <scale>100 100 100</scale>
              <uri>model://construction_cone/meshes/construction_cone.dae</uri>
            </mesh>
          </geometry>
          <max_contacts>10</max_contacts>
          <surface>
            <contact>
              <ode/>
            </contact>
            <bounce/>
            <friction>
              <torsional>
                <ode/>
              </torsional>
              <ode/>
            </friction>
          </surface>
        </collision>
        <visual name='visual'>
          <geometry>
            <mesh>
              <scale>100 100 100</scale>
              <uri>model://construction_cone/meshes/construction_cone.dae</uri>
            </mesh>
          </geometry>
        </visual>
        <self_collide>0</self_collide>
        <inertial>
          <pose>0 0 0 0 -0 0</pose>
          <inertia>
            <ixx>1</ixx>
            <ixy>0</ixy>
            <ixz>0</ixz>
            <iyy>1</iyy>
            <iyz>0</iyz>
            <izz>1</izz>
          </inertia>
          <mass>1</mass>
        </inertial>
        <enable_wind>0</enable_wind>
        <kinematic>0</kinematic>
      </link>
      <pose>1.05231 3.16013 -0 0 -1e-06 0</pose>
    </model>
    <model name='Construction Cone_clone_2'>
      <link name='link'>
        <collision name='collision'>
          <geometry>
            <mesh>
              <scale>100 100 100</scale>
              <uri>model://construction_cone/meshes/construction_cone.dae</uri>
            </mesh>
          </geometry>
          <max_contacts>10</max_contacts>
          <surface>
            <contact>
              <ode/>
            </contact>
            <bounce/>
            <friction>
              <torsional>
                <ode/>
              </torsional>
              <ode/>
            </friction>
          </surface>
        </collision>
        <visual name='visual'>
          <geometry>
            <mesh>
              <scale>100 100 100</scale>
              <uri>model://construction_cone/meshes/construction_cone.dae</uri>
            </mesh>
          </geometry>
        </visual>
        <self_collide>0</self_collide>
        <inertial>
          <pose>0 0 0 0 -0 0</pose>
          <inertia>
            <ixx>1</ixx>
            <ixy>0</ixy>
            <ixz>0</ixz>
            <iyy>1</iyy>
            <iyz>0</iyz>
            <izz>1</izz>
          </inertia>
          <mass>1</mass>
        </inertial>
        <enable_wind>0</enable_wind>
        <kinematic>0</kinematic>
      </link>
      <pose>3.06868 2.71587 -0 0 -1e-06 0</pose>
    </model>
    <model name='Construction Cone_clone_3'>
      <link name='link'>
        <collision name='collision'>
          <geometry>
            <mesh>
              <scale>100 100 100</scale>
              <uri>model://construction_cone/meshes/construction_cone.dae</uri>
            </mesh>
          </geometry>
          <max_contacts>10</max_contacts>
          <surface>
            <contact>
              <ode/>
            </contact>
            <bounce/>
            <friction>
              <torsional>
                <ode/>
              </torsional>
              <ode/>
            </friction>
          </surface>
        </collision>
        <visual name='visual'>
          <geometry>
            <mesh>
              <scale>100 100 100</scale>
              <uri>model://construction_cone/meshes/construction_cone.dae</uri>
            </mesh>
          </geometry>
        </visual>
        <self_collide>0</self_collide>
        <inertial>
          <pose>0 0 0 0 -0 0</pose>
          <inertia>
            <ixx>1</ixx>
            <ixy>0</ixy>
            <ixz>0</ixz>
            <iyy>1</iyy>
            <iyz>0</iyz>
            <izz>1</izz>
          </inertia>
          <mass>1</mass>
        </inertial>
        <enable_wind>0</enable_wind>
        <kinematic>0</kinematic>
      </link>
      <pose>4.85707 1.96912 -0 0 -1e-06 0</pose>
    </model>
    <model name='Construction Cone_clone_4'>
      <link name='link'>
        <collision name='collision'>
          <geometry>
            <mesh>
              <scale>100 100 100</scale>
              <uri>model://construction_cone/meshes/construction_cone.dae</uri>
            </mesh>
          </geometry>
          <max_contacts>10</max_contacts>
          <surface>
            <contact>
              <ode/>
            </contact>
            <bounce/>
            <friction>
              <torsional>
                <ode/>
              </torsional>
              <ode/>
            </friction>
          </surface>
        </collision>
        <visual name='visual'>
          <geometry>
            <mesh>
              <scale>100 100 100</scale>
              <uri>model://construction_cone/meshes/construction_cone.dae</uri>
            </mesh>
          </geometry>
        </visual>
        <self_collide>0</self_collide>
        <inertial>
          <pose>0 0 0 0 -0 0</pose>
          <inertia>
            <ixx>1</ixx>
            <ixy>0</ixy>
            <ixz>0</ixz>
            <iyy>1</iyy>
            <iyz>0</iyz>
            <izz>1</izz>
          </inertia>
          <mass>1</mass>
        </inertial>
        <enable_wind>0</enable_wind>
        <kinematic>0</kinematic>
      </link>
      <pose>6.58089 1.038 -0 0 -1e-06 0</pose>
    </model>
    <model name='Construction Cone_clone_5'>
      <link name='link'>
        <collision name='collision'>
          <geometry>
            <mesh>
              <scale>100 100 100</scale>
              <uri>model://construction_cone/meshes/construction_cone.dae</uri>
            </mesh>
          </geometry>
          <max_contacts>10</max_contacts>
          <surface>
            <contact>
              <ode/>
            </contact>
            <bounce/>
            <friction>
              <torsional>
                <ode/>
              </torsional>
              <ode/>
            </friction>
          </surface>
        </collision>
        <visual name='visual'>
          <geometry>
            <mesh>
              <scale>100 100 100</scale>
              <uri>model://construction_cone/meshes/construction_cone.dae</uri>
            </mesh>
          </geometry>
        </visual>
        <self_collide>0</self_collide>
        <inertial>
          <pose>0 0 0 0 -0 0</pose>
          <inertia>
            <ixx>1</ixx>
            <ixy>0</ixy>
            <ixz>0</ixz>
            <iyy>1</iyy>
            <iyz>0</iyz>
            <izz>1</izz>
          </inertia>
          <mass>1</mass>
        </inertial>
        <enable_wind>0</enable_wind>
        <kinematic>0</kinematic>
      </link>
      <pose>0.324463 -1.42655 -0 0 -1e-06 0</pose>
    </model>
    <model name='Construction Cone_clone_6'>
      <link name='link'>
        <collision name='collision'>
          <geometry>
            <mesh>
              <scale>100 100 100</scale>
              <uri>model://construction_cone/meshes/construction_cone.dae</uri>
            </mesh>
          </geometry>
          <max_contacts>10</max_contacts>
          <surface>
            <contact>
              <ode/>
            </contact>
            <bounce/>
            <friction>
              <torsional>
                <ode/>
              </torsional>
              <ode/>
            </friction>
          </surface>
        </collision>
        <visual name='visual'>
          <geometry>
            <mesh>
              <scale>100 100 100</scale>
              <uri>model://construction_cone/meshes/construction_cone.dae</uri>
            </mesh>
          </geometry>
        </visual>
        <self_collide>0</self_collide>
        <inertial>
          <pose>0 0 0 0 -0 0</pose>
          <inertia>
            <ixx>1</ixx>
            <ixy>0</ixy>
            <ixz>0</ixz>
            <iyy>1</iyy>
            <iyz>0</iyz>
            <izz>1</izz>
          </inertia>
          <mass>1</mass>
        </inertial>
        <enable_wind>0</enable_wind>
        <kinematic>0</kinematic>
      </link>
      <pose>2.52207 -1.03189 -0 0 -1e-06 0</pose>
    </model>
    <model name='Construction Cone_clone_7'>
      <link name='link'>
        <collision name='collision'>
          <geometry>
            <mesh>
              <scale>100 100 100</scale>
              <uri>model://construction_cone/meshes/construction_cone.dae</uri>
            </mesh>
          </geometry>
          <max_contacts>10</max_contacts>
          <surface>
            <contact>
              <ode/>
            </contact>
            <bounce/>
            <friction>
              <torsional>
                <ode/>
              </torsional>
              <ode/>
            </friction>
          </surface>
        </collision>
        <visual name='visual'>
          <geometry>
            <mesh>
              <scale>100 100 100</scale>
              <uri>model://construction_cone/meshes/construction_cone.dae</uri>
            </mesh>
          </geometry>
        </visual>
        <self_collide>0</self_collide>
        <inertial>
          <pose>0 0 0 0 -0 0</pose>
          <inertia>
            <ixx>1</ixx>
            <ixy>0</ixy>
            <ixz>0</ixz>
            <iyy>1</iyy>
            <iyz>0</iyz>
            <izz>1</izz>
          </inertia>
          <mass>1</mass>
        </inertial>
        <enable_wind>0</enable_wind>
        <kinematic>0</kinematic>
      </link>
      <pose>4.44511 -2.0877 -0 0 -1e-06 0</pose>
    </model>
    <model name='Construction Cone_clone_8'>
      <link name='link'>
        <collision name='collision'>
          <geometry>
            <mesh>
              <scale>100 100 100</scale>
              <uri>model://construction_cone/meshes/construction_cone.dae</uri>
            </mesh>
          </geometry>
          <max_contacts>10</max_contacts>
          <surface>
            <contact>
              <ode/>
            </contact>
            <bounce/>
            <friction>
              <torsional>
                <ode/>
              </torsional>
              <ode/>
            </friction>
          </surface>
        </collision>
        <visual name='visual'>
          <geometry>
            <mesh>
              <scale>100 100 100</scale>
              <uri>model://construction_cone/meshes/construction_cone.dae</uri>
            </mesh>
          </geometry>
        </visual>
        <self_collide>0</self_collide>
        <inertial>
          <pose>0 0 0 0 -0 0</pose>
          <inertia>
            <ixx>1</ixx>
            <ixy>0</ixy>
            <ixz>0</ixz>
            <iyy>1</iyy>
            <iyz>0</iyz>
            <izz>1</izz>
          </inertia>
          <mass>1</mass>
        </inertial>
        <enable_wind>0</enable_wind>
        <kinematic>0</kinematic>
      </link>
      <pose>-1.59831 -3.37381 -0 0 -1e-06 0</pose>
    </model>
    <model name='Construction Cone_clone_9'>
      <link name='link'>
        <collision name='collision'>
          <geometry>
            <mesh>
              <scale>100 100 100</scale>
              <uri>model://construction_cone/meshes/construction_cone.dae</uri>
            </mesh>
          </geometry>
          <max_contacts>10</max_contacts>
          <surface>
            <contact>
              <ode/>
            </contact>
            <bounce/>
            <friction>
              <torsional>
                <ode/>
              </torsional>
              <ode/>
            </friction>
          </surface>
        </collision>
        <visual name='visual'>
          <geometry>
            <mesh>
              <scale>100 100 100</scale>
              <uri>model://construction_cone/meshes/construction_cone.dae</uri>
            </mesh>
          </geometry>
        </visual>
        <self_collide>0</self_collide>
        <inertial>
          <pose>0 0 0 0 -0 0</pose>
          <inertia>
            <ixx>1</ixx>
            <ixy>0</ixy>
            <ixz>0</ixz>
            <iyy>1</iyy>
            <iyz>0</iyz>
            <izz>1</izz>
          </inertia>
          <mass>1</mass>
        </inertial>
        <enable_wind>0</enable_wind>
        <kinematic>0</kinematic>
      </link>
      <pose>-5 3 -0 0 -1e-06 0</pose>
    </model>
    <model name='Construction Cone_clone_10'>
      <link name='link'>
        <collision name='collision'>
          <geometry>
            <mesh>
              <scale>100 100 100</scale>
              <uri>model://construction_cone/meshes/construction_cone.dae</uri>
            </mesh>
          </geometry>
          <max_contacts>10</max_contacts>
          <surface>
            <contact>
              <ode/>
            </contact>
            <bounce/>
            <friction>
              <torsional>
                <ode/>
              </torsional>
              <ode/>
            </friction>
          </surface>
        </collision>
        <visual name='visual'>
          <geometry>
            <mesh>
              <scale>100 100 100</scale>
              <uri>model://construction_cone/meshes/construction_cone.dae</uri>
            </mesh>
          </geometry>
        </visual>
        <self_collide>0</self_collide>
        <inertial>
          <pose>0 0 0 0 -0 0</pose>
          <inertia>
            <ixx>1</ixx>
            <ixy>0</ixy>
            <ixz>0</ixz>
            <iyy>1</iyy>
            <iyz>0</iyz>
            <izz>1</izz>
          </inertia>
          <mass>1</mass>
        </inertial>
        <enable_wind>0</enable_wind>
        <kinematic>0</kinematic>
      </link>
      <pose>-2.47812 4.44463 -0 0 -1e-06 0</pose>
    </model>
    <model name='Construction Cone_clone_11'>
      <link name='link'>
        <collision name='collision'>
          <geometry>
            <mesh>
              <scale>100 100 100</scale>
              <uri>model://construction_cone/meshes/construction_cone.dae</uri>
            </mesh>
          </geometry>
          <max_contacts>10</max_contacts>
          <surface>
            <contact>
              <ode/>
            </contact>
            <bounce/>
            <friction>
              <torsional>
                <ode/>
              </torsional>
              <ode/>
            </friction>
          </surface>
        </collision>
        <visual name='visual'>
          <geometry>
            <mesh>
              <scale>100 100 100</scale>
              <uri>model://construction_cone/meshes/construction_cone.dae</uri>
            </mesh>
          </geometry>
        </visual>
        <self_collide>0</self_collide>
        <inertial>
          <pose>0 0 0 0 -0 0</pose>
          <inertia>
            <ixx>1</ixx>
            <ixy>0</ixy>
            <ixz>0</ixz>
            <iyy>1</iyy>
            <iyz>0</iyz>
            <izz>1</izz>
          </inertia>
          <mass>1</mass>
        </inertial>
        <enable_wind>0</enable_wind>
        <kinematic>0</kinematic>
      </link>
      <pose>-4.19381 6.02527 -0 0 -1e-06 0</pose>
    </model>
    <model name='Construction Cone_clone_12'>
      <link name='link'>
        <collision name='collision'>
          <geometry>
            <mesh>
              <scale>100 100 100</scale>
              <uri>model://construction_cone/meshes/construction_cone.dae</uri>
            </mesh>
          </geometry>
          <max_contacts>10</max_contacts>
          <surface>
            <contact>
              <ode/>
            </contact>
            <bounce/>
            <friction>
              <torsional>
                <ode/>
              </torsional>
              <ode/>
            </friction>
          </surface>
        </collision>
        <visual name='visual'>
          <geometry>
            <mesh>
              <scale>100 100 100</scale>
              <uri>model://construction_cone/meshes/construction_cone.dae</uri>
            </mesh>
          </geometry>
        </visual>
        <self_collide>0</self_collide>
        <inertial>
          <pose>0 0 0 0 -0 0</pose>
          <inertia>
            <ixx>1</ixx>
            <ixy>0</ixy>
            <ixz>0</ixz>
            <iyy>1</iyy>
            <iyz>0</iyz>
            <izz>1</izz>
          </inertia>
          <mass>1</mass>
        </inertial>
        <enable_wind>0</enable_wind>
        <kinematic>0</kinematic>
      </link>
      <pose>-6.70731 5.24393 -0 0 -1e-06 0</pose>
    </model>


    <model name="autocar">
      <pose>0 0 0.0 0 0 0</pose>

      <link name='base_link' />

      <joint name='chassis_link_joint' type='fixed'>
        <pose>0.0 0.0 0.0 0 0 0</pose>
        <parent>base_link</parent>
        <child>chassis_link</child>
      </joint>

      <joint name="hokuyo_joint" type="fixed">
        <parent>base_link</parent>
        <child>hokuyo_link</child>
        <pose>0 0 0 0 0 0</pose>
        <axis>
          <xyz>0 0 1</xyz>
        </axis>
      </joint>

      <link name="hokuyo_link">
        <sensor name="head_hokuyo_sensor" type="ray">
          <always_on>true</always_on>
          <visualize>true</visualize>
          <pose relative_to='base_link'>0 0 1.7 0 0 1.5708</pose>
          <update_rate>40</update_rate>
          <ray>
            <scan>
              <horizontal>
                <samples>720</samples>
                <resolution>1.000000</resolution>
                <min_angle>0</min_angle>
                <max_angle>6.28318530718</max_angle>
              </horizontal>
            </scan>
            <range>
              <min>0.120000</min>
              <max>30.0</max>
              <resolution>0.010</resolution>
            </range>
            <noise>
              <type>gaussian</type>
              <mean>0.0</mean>
              <stddev>0.01</stddev>
            </noise>
          </ray>
          <plugin name="gazebo_ros_head_hokuyo_controller" filename="libgazebo_ros_ray_sensor.so">
            <ros>
              <remapping>~/out:=scan</remapping>
            </ros>
            <output_type>sensor_msgs/LaserScan</output_type>
            <frame_name>hokuyo_link</frame_name>
          </plugin>
        </sensor>
      </link>

      <link name='chassis_link'>
        <inertial>
          <pose>1e-06 0.07307 0.65096 0 -0 0</pose>
          <mass>1580</mass>
          <inertia>
            <ixx>1997.86</ixx>
            <ixy>-3e-05</ixy>
            <ixz>-1e-06</ixz>
            <iyy>442.769</iyy>
            <iyz>62.5206</iyz>
            <izz>2238.05</izz>
          </inertia>
        </inertial>
        <collision name='chassis_link_fixed_joint_lump__chassis_link_collision'>
          <pose>0 0 0.46936 0 -0 0</pose>
          <geometry>
            <mesh>
              <scale>0.001 0.001 0.001</scale>
              <uri>model://autocar/meshes/chassis_link.stl</uri>
            </mesh>
          </geometry>
          <surface>
            <contact>
              <ode />
            </contact>
            <friction>
              <ode>
                <mu>0.2</mu>
                <mu2>0.2</mu2>
              </ode>
            </friction>
          </surface>
        </collision>
        <collision name='chassis_link_fixed_joint_lump__spoiler_link_collision_1'>
          <pose>0 0.05 0.41936 1.5708 -0 3.14159</pose>
          <geometry>
            <mesh>
              <scale>0.001 0.001 0.001</scale>
              <uri>model://autocar/meshes/spoiler.stl</uri>
            </mesh>
          </geometry>
          <surface>
            <contact>
              <ode />
            </contact>
            <friction>
              <ode>
                <mu>0.2</mu>
                <mu2>0.2</mu2>
              </ode>
            </friction>
          </surface>
        </collision>
        <visual name='chassis_link_fixed_joint_lump__chassis_link_visual'>
          <pose>0 0 0.46936 0 -0 0</pose>
          <geometry>
            <mesh>
              <scale>0.001 0.001 0.001</scale>
              <uri>model://autocar/meshes/chassis_link.stl</uri>
            </mesh>
          </geometry>
        </visual>
        <visual name='chassis_link_fixed_joint_lump__spoiler_link_visual_1'>
          <pose>0 0.05 0.41936 1.5708 -0 3.14159</pose>
          <geometry>
            <mesh>
              <scale>0.001 0.001 0.001</scale>
              <uri>model://autocar/meshes/spoiler.stl</uri>
            </mesh>
          </geometry>
        </visual>
        <!-- <velocity_decay/> -->
        <!--  <gravity>1</gravity> -->
        <!--  <gravity>1</gravity> -->
        <!-- <velocity_decay/> -->
        <self_collide>1</self_collide>
        <!--  <gravity>1</gravity> -->
      </link>

      <joint name='bl_axle' type='revolute'>
        <pose relative_to='chassis_link'>-0.875 -1.01364 0.324997 0 -0 0</pose>
        <parent>chassis_link</parent>
        <child>bl_1</child>
        <axis>
          <xyz>-1 0 0</xyz>
          <dynamics>
            <friction>12.031606150200002</friction>
          </dynamics>
        </axis>
      </joint>
      <link name='bl_1'>
        <pose relative_to='bl_axle'>0 0 0 0 -0 0</pose>
        <inertial>
          <pose>-0.0377 0 -0 0 -0 0</pose>
          <mass>24.5</mass>
          <inertia>
            <ixx>1.84514</ixx>
            <ixy>0</ixy>
            <ixz>0</ixz>
            <iyy>1.04961</iyy>
            <iyz>0</iyz>
            <izz>1.04961</izz>
          </inertia>
        </inertial>
        <collision name='bl_1_collision'>
          <pose relative_to='bl_axle'>0 0 0 0 1.5708 0</pose>
          <geometry>
            <cylinder>
              <radius>.3425</radius>
              <length>.22</length>
            </cylinder>
          </geometry>
          <surface>
            <contact>
              <ode />
            </contact>
            <friction>
              <ode>
                <mu>1.7</mu>
                <mu2>1.7</mu2>
              </ode>
            </friction>
          </surface>
        </collision>
        <visual name='bl_1_visual'>
          <pose>0.875 1.0136 0.1444 0 -0 0</pose>
          <geometry>
            <mesh>
              <scale>0.001 0.001 0.001</scale>
              <uri>model://autocar/meshes/bl_1.stl</uri>
            </mesh>
          </geometry>
        </visual>
        <!--  <gravity>1</gravity> -->
        <!-- <velocity_decay/> -->
        <self_collide>1</self_collide>
      </link>
      <joint name='br_axle' type='revolute'>
        <pose relative_to='chassis_link'>0.875 -1.01364 0.324997 0 -0 0</pose>
        <parent>chassis_link</parent>
        <child>br_1</child>
        <axis>
          <xyz>-1 0 0</xyz>
          <dynamics>
            <friction>12.031606150200002</friction>
          </dynamics>
        </axis>
      </joint>
      <link name='br_1'>
        <pose relative_to='br_axle'>0 0 0 0 -0 0</pose>
        <inertial>
          <pose>-0.0377 0 -0 0 -0 0</pose>
          <mass>24.5</mass>
          <inertia>
            <ixx>1.84514</ixx>
            <ixy>0</ixy>
            <ixz>0</ixz>
            <iyy>1.04961</iyy>
            <iyz>0</iyz>
            <izz>1.04961</izz>
          </inertia>
        </inertial>
        <collision name='br_1_collision'>
          <pose relative_to='br_axle'>0 0 0 0 1.5708 0</pose>
          <geometry>
            <cylinder>
              <radius>.3425</radius>
              <length>.22</length>
            </cylinder>
          </geometry>
          <surface>
            <contact>
              <ode />
            </contact>
            <friction>
              <ode>
                <mu>1.7</mu>
                <mu2>1.7</mu2>
              </ode>
            </friction>
          </surface>
        </collision>
        <visual name='br_1_visual'>
          <pose>-0.875 1.0136 0.1444 0 -0 0</pose>
          <geometry>
            <mesh>
              <scale>0.001 0.001 0.001</scale>
              <uri>model://autocar/meshes/br_1.stl</uri>
            </mesh>
          </geometry>
        </visual>
        <!--  <gravity>1</gravity> -->
        <!-- <velocity_decay/> -->
        <self_collide>1</self_collide>
      </link>
      <joint name='l_steer' type='revolute'>
        <pose relative_to='chassis_link'>-0.825 1.51736 0.324997 0 -0 0</pose>
        <parent>chassis_link</parent>
        <child>l_steer_1</child>
        <axis>
          <xyz>0 0 1</xyz>
          <limit>
            <lower>-0.95</lower>
            <upper>0.95</upper>
          </limit>
          <dynamics>
            <friction>18.0474092253</friction>
          </dynamics>
        </axis>
      </joint>
      <link name='l_steer_1'>
        <pose relative_to='l_steer'>0 0 0 0 -0 0</pose>
        <inertial>
          <pose>0.003381 0 0.02162 0 -0 0</pose>
          <mass>1</mass>
          <inertia>
            <ixx>1</ixx>
            <ixy>0</ixy>
            <ixz>0</ixz>
            <iyy>1</iyy>
            <iyz>0</iyz>
            <izz>1</izz>
          </inertia>
        </inertial>
        <!--  <gravity>1</gravity> -->
        <!-- <velocity_decay/> -->
        <self_collide>1</self_collide>
      </link>

      <joint name='fl_axle' type='revolute'>
        <pose relative_to='l_steer_1'>-0.05 0 0 0 -0 0</pose>
        <parent>l_steer_1</parent>
        <child>fl_1</child>
        <axis>
          <xyz>-1 0 0</xyz>
          <dynamics>
            <friction>12.031606150200002</friction>
          </dynamics>
        </axis>
      </joint>
      <link name='fl_1'>
        <pose relative_to='fl_axle'>0 0 0 0 -0 0</pose>
        <inertial>
          <pose>-0.0377 0 -0 0 -0 0</pose>
          <mass>24.5</mass>
          <inertia>
            <ixx>1.84514</ixx>
            <ixy>0</ixy>
            <ixz>0</ixz>
            <iyy>1.04961</iyy>
            <iyz>0</iyz>
            <izz>1.04961</izz>
          </inertia>
        </inertial>
        <collision name='fl_1_collision'>
          <pose>0.875 -1.5174 0.1444 0 -0 0</pose>
          <geometry>
            <mesh>
              <scale>0.001 0.001 0.001</scale>
              <uri>model://autocar/meshes/fl_1.stl</uri>
            </mesh>
          </geometry>
          <surface>
            <contact>
              <ode />
            </contact>
            <friction>
              <ode>
                <mu>1.1</mu>
                <mu2>1.1</mu2>
              </ode>
            </friction>
          </surface>
        </collision>
        <visual name='fl_1_visual'>
          <pose>0.875 -1.5174 0.1444 0 -0 0</pose>
          <geometry>
            <mesh>
              <scale>0.001 0.001 0.001</scale>
              <uri>model://autocar/meshes/fl_1.stl</uri>
            </mesh>
          </geometry>
        </visual>
        <!--  <gravity>1</gravity> -->
        <!-- <velocity_decay/> -->
        <self_collide>1</self_collide>
      </link>
      <joint name='r_steer' type='revolute'>
        <pose relative_to='chassis_link'>0.825 1.51736 0.324997 0 -0 0</pose>
        <parent>chassis_link</parent>
        <child>r_steer_1</child>
        <axis>
          <xyz>0 0 1</xyz>
          <limit>
            <lower>-0.95</lower>
            <upper>0.95</upper>
          </limit>
          <dynamics>
            <damping>0.01</damping>
            <friction>18.0474092253</friction>
          </dynamics>
        </axis>
      </joint>
      <link name='r_steer_1'>
        <pose relative_to='r_steer'>0 0 0 0 -0 0</pose>
        <inertial>
          <pose>0.003381 0 0.02162 0 -0 0</pose>
          <mass>1</mass>
          <inertia>
            <ixx>1</ixx>
            <ixy>0</ixy>
            <ixz>0</ixz>
            <iyy>1</iyy>
            <iyz>0</iyz>
            <izz>1</izz>
          </inertia>
        </inertial>
        <!--  <gravity>1</gravity> -->
        <!-- <velocity_decay/> -->
        <self_collide>1</self_collide>
      </link>
      <joint name='fr_axle' type='revolute'>
        <pose relative_to='r_steer_1'>0.05 0 0 0 -0 0</pose>
        <parent>r_steer_1</parent>
        <child>fr_1</child>
        <axis>
          <xyz>-1 0 0</xyz>
          <dynamics>
            <friction>12.031606150200002</friction>
          </dynamics>
        </axis>
      </joint>
      <link name='fr_1'>
        <pose relative_to='fr_axle'>0 0 0 0 -0 0</pose>
        <inertial>
          <pose>-0.0377 0 -0 0 -0 0</pose>
          <mass>24.5</mass>
          <inertia>
            <ixx>1.84514</ixx>
            <ixy>0</ixy>
            <ixz>0</ixz>
            <iyy>1.04961</iyy>
            <iyz>0</iyz>
            <izz>1.04961</izz>
          </inertia>
        </inertial>
        <collision name='fr_1_collision'>
          <pose>-0.875 -1.5174 0.1444 0 -0 0</pose>
          <geometry>
            <mesh>
              <scale>0.001 0.001 0.001</scale>
              <uri>model://autocar/meshes/fr_1.stl</uri>
            </mesh>
          </geometry>
          <surface>
            <contact>
              <ode />
            </contact>
            <friction>
              <ode>
                <mu>1.7</mu>
                <mu2>1.7</mu2>
              </ode>
            </friction>
          </surface>
        </collision>
        <visual name='fr_1_visual'>
          <pose>-0.875 -1.5174 0.1444 0 -0 0</pose>
          <geometry>
            <mesh>
              <scale>0.001 0.001 0.001</scale>
              <uri>model://autocar/meshes/fr_1.stl</uri>
            </mesh>
          </geometry>
        </visual>
        <!--  <gravity>1</gravity> -->
        <!-- <velocity_decay/> -->
        <self_collide>1</self_collide>
      </link>

      <link name="steering_wheel" />

      <joint name="steering_joint" type="revolute">
        <pose>-0.002 0 0 0 0 0</pose>
        <parent>chassis_link</parent>
        <child>steering_wheel</child>
        <axis>
          <xyz>-0.964118 0.000768 0.265556</xyz>
          <limit>
            <lower>-100</lower>
            <upper>100</upper>
          </limit>
          <dynamics>
            <damping>1.0</damping>
          </dynamics>
          <use_parent_model_frame>true</use_parent_model_frame>
        </axis>
        <physics>
          <ode>
            <cfm_damping>1</cfm_damping>
          </ode>
        </physics>
      </joint>

      <plugin name='ackermann_drive' filename='libgazebo_ros_ackermann_drive.so'>

        <ros>
          
          <remapping>cmd_vel:=cmd_vel</remapping>
          <remapping>odom:=odom</remapping>
          <remapping>distance:=distance</remapping>
        </ros>

        <update_rate>100.0</update_rate>

        <!-- wheels -->
        <front_left_joint>fl_axle</front_left_joint>
        <front_right_joint>fr_axle</front_right_joint>
        <rear_left_joint>bl_axle</rear_left_joint>
        <rear_right_joint>br_axle</rear_right_joint>
        <left_steering_joint>l_steer</left_steering_joint>
        <right_steering_joint>r_steer</right_steering_joint>
        <steering_wheel_joint>steering_joint</steering_wheel_joint>


        <!-- Max absolute steer angle for tyre in radians-->
        <!-- Any cmd_vel angular z greater than this would be capped -->
        <max_steer>0.85</max_steer>

        <!-- Max absolute steering angle of steering wheel -->
        <!-- Max absolute steering angle of steering wheel -->
        <max_steering_angle>7.85</max_steering_angle>

        <!-- Max absolute linear speed in m/s -->
        <max_speed>20</max_speed>

        <!-- PID tuning -->
        <left_steering_pid_gain>4000 0 1</left_steering_pid_gain>
        <left_steering_i_range>0 0</left_steering_i_range>
        <right_steering_pid_gain>4000 0 1</right_steering_pid_gain>
        <right_steering_i_range>0 0</right_steering_i_range>
        <linear_velocity_pid_gain>4000 0 1</linear_velocity_pid_gain>
        <linear_velocity_i_range>0 0</linear_velocity_i_range>

        <!-- output -->
        <publish_odom>true</publish_odom>
        <publish_odom_tf>true</publish_odom_tf>
        <publish_wheel_tf>true</publish_wheel_tf>
        <publish_distance>true</publish_distance>

        <odometry_frame>odom</odometry_frame>
        <robot_base_frame>base_link</robot_base_frame>

      </plugin>

    </model>

  </world>
</sdf>
